[2024-02-13T13:52:43.869Z] [INFO] [QuoteVerificationService requestId.js:75] [hostname:SGXrinkai pid:1] [reqId=597a4c16f761463a9954043b84eef4b5]   <-- request GET /health [headers={"host":"localhost:8799","user-agent":"curl/7.81.0","accept":"*/*"}]
[2024-02-13T13:52:43.870Z] [INFO] [QuoteVerificationService configureCtxLoggerAndLogResponse.js:59] [hostname:SGXrinkai pid:1] [reqId=597a4c16f761463a9954043b84eef4b5]   --> response GET /health 200 took 1ms [headers={"request-id":"597a4c16f761463a9954043b84eef4b5","content-type":"application/json","content-length":"299"} body={"status":"OK","version":"1.0.0","lastChecked":"2024-02-13T13:52:35.543Z","componentStatus":{"VerificationCryptoService":{"status":"OK","version":"0.0.1","lastChecked":"2024-02-13T13:52:35.558Z"},"QuoteVerificationLibrary":{"status":"OK","version":"1.0.0","lastChecked":"2024-02-13T13:52:35.552Z"}}}]
[2024-02-13T13:53:35.573Z] [INFO] [QuoteVerificationService requestHandler.js:106] [hostname:SGXrinkai pid:1] [reqId=bd309adaa0c441e1b9e580218174dabc] Sending request to: https://localhost:8797/health

[2024-02-13T13:53:43.949Z] [INFO] [QuoteVerificationService requestId.js:75] [hostname:SGXrinkai pid:1] [reqId=81d78946066945ec8e2f61fb569d8ec5]   <-- request POST /attestation/sgx/dcap/v1/report [headers={"host":"localhost:8799","user-agent":"curl/7.81.0","accept":"*/*","content-type":"application/json","content-length":"6181"}]
[2024-02-13T13:53:43.962Z] [INFO] [QuoteVerificationService requestHandler.js:106] [hostname:SGXrinkai pid:1] [reqId=81d78946066945ec8e2f61fb569d8ec5] Sending request to: https://api.trustedservices.intel.com:443/sgx/certification/v4/tcb?fmspc=00706A100000&update=standard
[2024-02-13T13:53:43.965Z] [INFO] [QuoteVerificationService requestHandler.js:106] [hostname:SGXrinkai pid:1] [reqId=81d78946066945ec8e2f61fb569d8ec5] Sending request to: https://api.trustedservices.intel.com:443/sgx/certification/v4/qe/identity?update=standard
[2024-02-13T13:53:43.969Z] [INFO] [QuoteVerificationService requestHandler.js:106] [hostname:SGXrinkai pid:1] [reqId=81d78946066945ec8e2f61fb569d8ec5] Sending request to: https://api.trustedservices.intel.com:443/sgx/certification/v3/pckcrl?ca=processor&encoding=der
[2024-02-13T13:53:43.972Z] [INFO] [QuoteVerificationService requestHandler.js:106] [hostname:SGXrinkai pid:1] [reqId=81d78946066945ec8e2f61fb569d8ec5] Sending request to: https://certificates.trustedservices.intel.com:443/IntelSGXRootCA.der
[2024-02-13T13:53:44.153Z] [ERROR] [QuoteVerificationService requestHandler.js:136] [hostname:SGXrinkai pid:1] [reqId=81d78946066945ec8e2f61fb569d8ec5] Error while trying to GET https://certificates.trustedservices.intel.com:443/IntelSGXRootCA.der: {"details":{"code":"SELF_SIGNED_CERT_IN_CHAIN","stack":"Error: self-signed certificate in certificate chain\n    at AxiosError.from (/QVS/src/node_modules/axios/dist/node/axios.cjs:837:14)\n    at RedirectableRequest.handleRequestError (/QVS/src/node_modules/axios/dist/node/axios.cjs:3087:25)\n    at RedirectableRequest.emit (node:events:530:35)\n    at eventHandlers.<computed> (/QVS/src/node_modules/follow-redirects/index.js:38:24)\n    at ClientRequest.emit (node:events:518:28)\n    at TLSSocket.socketErrorListener (node:_http_client:495:9)\n    at TLSSocket.emit (node:events:518:28)\n    at emitErrorNT (node:internal/streams/destroy:169:8)\n    at emitErrorCloseNT (node:internal/streams/destroy:128:3)\n    at process.processTicksAndRejections (node:internal/process/task_queues:82:21)\n    at Axios.request (/QVS/src/node_modules/axios/dist/node/axios.cjs:3877:41)\n    at process.processTicksAndRejections (node:internal/process/task_queues:95:5)\n    at async nodeRequest (/QVS/src/common/nodeRequestHandler.js:88:26)\n    at async RequestHandler.sendRequest (/QVS/src/common/requestHandler.js:109:25)"},"name":"Error","message":"self-signed certificate in certificate chain","stack":"Error: self-signed certificate in certificate chain\n    at RequestHandler.sendRequest (/QVS/src/common/requestHandler.js:134:55)\n    at process.processTicksAndRejections (node:internal/process/task_queues:95:5)"}
[2024-02-13T13:53:44.154Z] [WARN] [QuoteVerificationService requestHandler.js:134] [hostname:SGXrinkai pid:1] [reqId=81d78946066945ec8e2f61fb569d8ec5] RuntimeError: self-signed certificate in certificate chain |     at RequestHandler.sendRequest (/QVS/src/common/requestHandler.js:134:55) |     at process.processTicksAndRejections (node:internal/process/task_queues:95:5) { |   details: { |     code: 'SELF_SIGNED_CERT_IN_CHAIN', |     stack: 'Error: self-signed certificate in certificate chain\n' + |       '    at AxiosError.from (/QVS/src/node_modules/axios/dist/node/axios.cjs:837:14)\n' + |       '    at RedirectableRequest.handleRequestError (/QVS/src/node_modules/axios/dist/node/axios.cjs:3087:25)\n' + |       '    at RedirectableRequest.emit (node:events:530:35)\n' + |       '    at eventHandlers.<computed> (/QVS/src/node_modules/follow-redirects/index.js:38:24)\n' + |       '    at ClientRequest.emit (node:events:518:28)\n' + |       '    at TLSSocket.socketErrorListener (node:_http_client:495:9)\n' + |       '    at TLSSocket.emit (node:events:518:28)\n' + |       '    at emitErrorNT (node:internal/streams/destroy:169:8)\n' + |       '    at emitErrorCloseNT (node:internal/streams/destroy:128:3)\n' + |       '    at process.processTicksAndRejections (node:internal/process/task_queues:82:21)\n' + |       '    at Axios.request (/QVS/src/node_modules/axios/dist/node/axios.cjs:3877:41)\n' + |       '    at process.processTicksAndRejections (node:internal/process/task_queues:95:5)\n' + |       '    at async nodeRequest (/QVS/src/common/nodeRequestHandler.js:88:26)\n' + |       '    at async RequestHandler.sendRequest (/QVS/src/common/requestHandler.js:109:25)' |   } | } Request ended with an error. Retrying call host with address: certificates.trustedservices.intel.com:443 ... Attempt number: 1 out of 2
[2024-02-13T13:53:44.254Z] [INFO] [QuoteVerificationService requestHandler.js:106] [hostname:SGXrinkai pid:1] [reqId=81d78946066945ec8e2f61fb569d8ec5] Sending request to: https://certificates.trustedservices.intel.com:443/IntelSGXRootCA.der
[2024-02-13T13:53:44.300Z] [ERROR] [QuoteVerificationService requestHandler.js:136] [hostname:SGXrinkai pid:1] [reqId=81d78946066945ec8e2f61fb569d8ec5] Error while trying to GET https://certificates.trustedservices.intel.com:443/IntelSGXRootCA.der: {"details":{"code":"SELF_SIGNED_CERT_IN_CHAIN","stack":"Error: self-signed certificate in certificate chain\n    at AxiosError.from (/QVS/src/node_modules/axios/dist/node/axios.cjs:837:14)\n    at RedirectableRequest.handleRequestError (/QVS/src/node_modules/axios/dist/node/axios.cjs:3087:25)\n    at RedirectableRequest.emit (node:events:530:35)\n    at eventHandlers.<computed> (/QVS/src/node_modules/follow-redirects/index.js:38:24)\n    at ClientRequest.emit (node:events:518:28)\n    at TLSSocket.socketErrorListener (node:_http_client:495:9)\n    at TLSSocket.emit (node:events:518:28)\n    at emitErrorNT (node:internal/streams/destroy:169:8)\n    at emitErrorCloseNT (node:internal/streams/destroy:128:3)\n    at process.processTicksAndRejections (node:internal/process/task_queues:82:21)\n    at Axios.request (/QVS/src/node_modules/axios/dist/node/axios.cjs:3877:41)\n    at process.processTicksAndRejections (node:internal/process/task_queues:95:5)\n    at async nodeRequest (/QVS/src/common/nodeRequestHandler.js:88:26)\n    at async RequestHandler.sendRequest (/QVS/src/common/requestHandler.js:109:25)"},"name":"Error","message":"self-signed certificate in certificate chain","stack":"Error: self-signed certificate in certificate chain\n    at RequestHandler.sendRequest (/QVS/src/common/requestHandler.js:134:55)\n    at process.processTicksAndRejections (node:internal/process/task_queues:95:5)"}
[2024-02-13T13:53:44.300Z] [WARN] [QuoteVerificationService requestHandler.js:134] [hostname:SGXrinkai pid:1] [reqId=81d78946066945ec8e2f61fb569d8ec5] RuntimeError: self-signed certificate in certificate chain |     at RequestHandler.sendRequest (/QVS/src/common/requestHandler.js:134:55) |     at process.processTicksAndRejections (node:internal/process/task_queues:95:5) { |   details: { |     code: 'SELF_SIGNED_CERT_IN_CHAIN', |     stack: 'Error: self-signed certificate in certificate chain\n' + |       '    at AxiosError.from (/QVS/src/node_modules/axios/dist/node/axios.cjs:837:14)\n' + |       '    at RedirectableRequest.handleRequestError (/QVS/src/node_modules/axios/dist/node/axios.cjs:3087:25)\n' + |       '    at RedirectableRequest.emit (node:events:530:35)\n' + |       '    at eventHandlers.<computed> (/QVS/src/node_modules/follow-redirects/index.js:38:24)\n' + |       '    at ClientRequest.emit (node:events:518:28)\n' + |       '    at TLSSocket.socketErrorListener (node:_http_client:495:9)\n' + |       '    at TLSSocket.emit (node:events:518:28)\n' + |       '    at emitErrorNT (node:internal/streams/destroy:169:8)\n' + |       '    at emitErrorCloseNT (node:internal/streams/destroy:128:3)\n' + |       '    at process.processTicksAndRejections (node:internal/process/task_queues:82:21)\n' + |       '    at Axios.request (/QVS/src/node_modules/axios/dist/node/axios.cjs:3877:41)\n' + |       '    at process.processTicksAndRejections (node:internal/process/task_queues:95:5)\n' + |       '    at async nodeRequest (/QVS/src/common/nodeRequestHandler.js:88:26)\n' + |       '    at async RequestHandler.sendRequest (/QVS/src/common/requestHandler.js:109:25)' |   } | } Request ended with an error. Retrying call host with address: certificates.trustedservices.intel.com:443 ... Attempt number: 2 out of 2
[2024-02-13T13:53:44.601Z] [INFO] [QuoteVerificationService requestHandler.js:106] [hostname:SGXrinkai pid:1] [reqId=81d78946066945ec8e2f61fb569d8ec5] Sending request to: https://certificates.trustedservices.intel.com:443/IntelSGXRootCA.der
[2024-02-13T13:53:44.626Z] [ERROR] [QuoteVerificationService requestHandler.js:136] [hostname:SGXrinkai pid:1] [reqId=81d78946066945ec8e2f61fb569d8ec5] Error while trying to GET https://api.trustedservices.intel.com:443/sgx/certification/v4/qe/identity?update=standard: {"details":{"code":"UNABLE_TO_GET_ISSUER_CERT_LOCALLY","stack":"Error: unable to get local issuer certificate\n    at AxiosError.from (/QVS/src/node_modules/axios/dist/node/axios.cjs:837:14)\n    at RedirectableRequest.handleRequestError (/QVS/src/node_modules/axios/dist/node/axios.cjs:3087:25)\n    at RedirectableRequest.emit (node:events:530:35)\n    at eventHandlers.<computed> (/QVS/src/node_modules/follow-redirects/index.js:38:24)\n    at ClientRequest.emit (node:events:518:28)\n    at TLSSocket.socketErrorListener (node:_http_client:495:9)\n    at TLSSocket.emit (node:events:518:28)\n    at emitErrorNT (node:internal/streams/destroy:169:8)\n    at emitErrorCloseNT (node:internal/streams/destroy:128:3)\n    at process.processTicksAndRejections (node:internal/process/task_queues:82:21)\n    at Axios.request (/QVS/src/node_modules/axios/dist/node/axios.cjs:3877:41)\n    at process.processTicksAndRejections (node:internal/process/task_queues:95:5)\n    at async nodeRequest (/QVS/src/common/nodeRequestHandler.js:88:26)\n    at async RequestHandler.sendRequest (/QVS/src/common/requestHandler.js:109:25)"},"name":"Error","message":"unable to get local issuer certificate","stack":"Error: unable to get local issuer certificate\n    at RequestHandler.sendRequest (/QVS/src/common/requestHandler.js:134:55)\n    at process.processTicksAndRejections (node:internal/process/task_queues:95:5)"}
[2024-02-13T13:53:44.627Z] [WARN] [QuoteVerificationService requestHandler.js:134] [hostname:SGXrinkai pid:1] [reqId=81d78946066945ec8e2f61fb569d8ec5] RuntimeError: unable to get local issuer certificate |     at RequestHandler.sendRequest (/QVS/src/common/requestHandler.js:134:55) |     at process.processTicksAndRejections (node:internal/process/task_queues:95:5) { |   details: { |     code: 'UNABLE_TO_GET_ISSUER_CERT_LOCALLY', |     stack: 'Error: unable to get local issuer certificate\n' + |       '    at AxiosError.from (/QVS/src/node_modules/axios/dist/node/axios.cjs:837:14)\n' + |       '    at RedirectableRequest.handleRequestError (/QVS/src/node_modules/axios/dist/node/axios.cjs:3087:25)\n' + |       '    at RedirectableRequest.emit (node:events:530:35)\n' + |       '    at eventHandlers.<computed> (/QVS/src/node_modules/follow-redirects/index.js:38:24)\n' + |       '    at ClientRequest.emit (node:events:518:28)\n' + |       '    at TLSSocket.socketErrorListener (node:_http_client:495:9)\n' + |       '    at TLSSocket.emit (node:events:518:28)\n' + |       '    at emitErrorNT (node:internal/streams/destroy:169:8)\n' + |       '    at emitErrorCloseNT (node:internal/streams/destroy:128:3)\n' + |       '    at process.processTicksAndRejections (node:internal/process/task_queues:82:21)\n' + |       '    at Axios.request (/QVS/src/node_modules/axios/dist/node/axios.cjs:3877:41)\n' + |       '    at process.processTicksAndRejections (node:internal/process/task_queues:95:5)\n' + |       '    at async nodeRequest (/QVS/src/common/nodeRequestHandler.js:88:26)\n' + |       '    at async RequestHandler.sendRequest (/QVS/src/common/requestHandler.js:109:25)' |   } | } Request ended with an error. Retrying call host with address: api.trustedservices.intel.com:443 ... Attempt number: 1 out of 1
[2024-02-13T13:53:44.644Z] [ERROR] [QuoteVerificationService requestHandler.js:136] [hostname:SGXrinkai pid:1] [reqId=81d78946066945ec8e2f61fb569d8ec5] Error while trying to GET https://api.trustedservices.intel.com:443/sgx/certification/v4/tcb?fmspc=00706A100000&update=standard: {"details":{"code":"UNABLE_TO_GET_ISSUER_CERT_LOCALLY","stack":"Error: unable to get local issuer certificate\n    at AxiosError.from (/QVS/src/node_modules/axios/dist/node/axios.cjs:837:14)\n    at RedirectableRequest.handleRequestError (/QVS/src/node_modules/axios/dist/node/axios.cjs:3087:25)\n    at RedirectableRequest.emit (node:events:530:35)\n    at eventHandlers.<computed> (/QVS/src/node_modules/follow-redirects/index.js:38:24)\n    at ClientRequest.emit (node:events:518:28)\n    at TLSSocket.socketErrorListener (node:_http_client:495:9)\n    at TLSSocket.emit (node:events:518:28)\n    at emitErrorNT (node:internal/streams/destroy:169:8)\n    at emitErrorCloseNT (node:internal/streams/destroy:128:3)\n    at process.processTicksAndRejections (node:internal/process/task_queues:82:21)\n    at Axios.request (/QVS/src/node_modules/axios/dist/node/axios.cjs:3877:41)\n    at process.processTicksAndRejections (node:internal/process/task_queues:95:5)\n    at async nodeRequest (/QVS/src/common/nodeRequestHandler.js:88:26)\n    at async RequestHandler.sendRequest (/QVS/src/common/requestHandler.js:109:25)"},"name":"Error","message":"unable to get local issuer certificate","stack":"Error: unable to get local issuer certificate\n    at RequestHandler.sendRequest (/QVS/src/common/requestHandler.js:134:55)\n    at process.processTicksAndRejections (node:internal/process/task_queues:95:5)"}
[2024-02-13T13:53:44.644Z] [WARN] [QuoteVerificationService requestHandler.js:134] [hostname:SGXrinkai pid:1] [reqId=81d78946066945ec8e2f61fb569d8ec5] RuntimeError: unable to get local issuer certificate |     at RequestHandler.sendRequest (/QVS/src/common/requestHandler.js:134:55) |     at process.processTicksAndRejections (node:internal/process/task_queues:95:5) { |   details: { |     code: 'UNABLE_TO_GET_ISSUER_CERT_LOCALLY', |     stack: 'Error: unable to get local issuer certificate\n' + |       '    at AxiosError.from (/QVS/src/node_modules/axios/dist/node/axios.cjs:837:14)\n' + |       '    at RedirectableRequest.handleRequestError (/QVS/src/node_modules/axios/dist/node/axios.cjs:3087:25)\n' + |       '    at RedirectableRequest.emit (node:events:530:35)\n' + |       '    at eventHandlers.<computed> (/QVS/src/node_modules/follow-redirects/index.js:38:24)\n' + |       '    at ClientRequest.emit (node:events:518:28)\n' + |       '    at TLSSocket.socketErrorListener (node:_http_client:495:9)\n' + |       '    at TLSSocket.emit (node:events:518:28)\n' + |       '    at emitErrorNT (node:internal/streams/destroy:169:8)\n' + |       '    at emitErrorCloseNT (node:internal/streams/destroy:128:3)\n' + |       '    at process.processTicksAndRejections (node:internal/process/task_queues:82:21)\n' + |       '    at Axios.request (/QVS/src/node_modules/axios/dist/node/axios.cjs:3877:41)\n' + |       '    at process.processTicksAndRejections (node:internal/process/task_queues:95:5)\n' + |       '    at async nodeRequest (/QVS/src/common/nodeRequestHandler.js:88:26)\n' + |       '    at async RequestHandler.sendRequest (/QVS/src/common/requestHandler.js:109:25)' |   } | } Request ended with an error. Retrying call host with address: api.trustedservices.intel.com:443 ... Attempt number: 1 out of 1
[2024-02-13T13:53:44.656Z] [ERROR] [QuoteVerificationService requestHandler.js:136] [hostname:SGXrinkai pid:1] [reqId=81d78946066945ec8e2f61fb569d8ec5] Error while trying to GET https://certificates.trustedservices.intel.com:443/IntelSGXRootCA.der: {"details":{"code":"SELF_SIGNED_CERT_IN_CHAIN","stack":"Error: self-signed certificate in certificate chain\n    at AxiosError.from (/QVS/src/node_modules/axios/dist/node/axios.cjs:837:14)\n    at RedirectableRequest.handleRequestError (/QVS/src/node_modules/axios/dist/node/axios.cjs:3087:25)\n    at RedirectableRequest.emit (node:events:530:35)\n    at eventHandlers.<computed> (/QVS/src/node_modules/follow-redirects/index.js:38:24)\n    at ClientRequest.emit (node:events:518:28)\n    at TLSSocket.socketErrorListener (node:_http_client:495:9)\n    at TLSSocket.emit (node:events:518:28)\n    at emitErrorNT (node:internal/streams/destroy:169:8)\n    at emitErrorCloseNT (node:internal/streams/destroy:128:3)\n    at process.processTicksAndRejections (node:internal/process/task_queues:82:21)\n    at Axios.request (/QVS/src/node_modules/axios/dist/node/axios.cjs:3877:41)\n    at process.processTicksAndRejections (node:internal/process/task_queues:95:5)\n    at async nodeRequest (/QVS/src/common/nodeRequestHandler.js:88:26)\n    at async RequestHandler.sendRequest (/QVS/src/common/requestHandler.js:109:25)"},"name":"Error","message":"self-signed certificate in certificate chain","stack":"Error: self-signed certificate in certificate chain\n    at RequestHandler.sendRequest (/QVS/src/common/requestHandler.js:134:55)\n    at process.processTicksAndRejections (node:internal/process/task_queues:95:5)"}
[2024-02-13T13:53:44.658Z] [ERROR] [QuoteVerificationService requestHandler.js:136] [hostname:SGXrinkai pid:1] [reqId=81d78946066945ec8e2f61fb569d8ec5] Error while trying to GET https://api.trustedservices.intel.com:443/sgx/certification/v3/pckcrl?ca=processor&encoding=der: {"details":{"code":"UNABLE_TO_GET_ISSUER_CERT_LOCALLY","stack":"Error: unable to get local issuer certificate\n    at AxiosError.from (/QVS/src/node_modules/axios/dist/node/axios.cjs:837:14)\n    at RedirectableRequest.handleRequestError (/QVS/src/node_modules/axios/dist/node/axios.cjs:3087:25)\n    at RedirectableRequest.emit (node:events:530:35)\n    at eventHandlers.<computed> (/QVS/src/node_modules/follow-redirects/index.js:38:24)\n    at ClientRequest.emit (node:events:518:28)\n    at TLSSocket.socketErrorListener (node:_http_client:495:9)\n    at TLSSocket.emit (node:events:518:28)\n    at emitErrorNT (node:internal/streams/destroy:169:8)\n    at emitErrorCloseNT (node:internal/streams/destroy:128:3)\n    at process.processTicksAndRejections (node:internal/process/task_queues:82:21)\n    at Axios.request (/QVS/src/node_modules/axios/dist/node/axios.cjs:3877:41)\n    at process.processTicksAndRejections (node:internal/process/task_queues:95:5)\n    at async nodeRequest (/QVS/src/common/nodeRequestHandler.js:88:26)\n    at async RequestHandler.sendRequest (/QVS/src/common/requestHandler.js:109:25)"},"name":"Error","message":"unable to get local issuer certificate","stack":"Error: unable to get local issuer certificate\n    at RequestHandler.sendRequest (/QVS/src/common/requestHandler.js:134:55)\n    at process.processTicksAndRejections (node:internal/process/task_queues:95:5)"}
[2024-02-13T13:53:44.658Z] [WARN] [QuoteVerificationService requestHandler.js:134] [hostname:SGXrinkai pid:1] [reqId=81d78946066945ec8e2f61fb569d8ec5] RuntimeError: unable to get local issuer certificate |     at RequestHandler.sendRequest (/QVS/src/common/requestHandler.js:134:55) |     at process.processTicksAndRejections (node:internal/process/task_queues:95:5) { |   details: { |     code: 'UNABLE_TO_GET_ISSUER_CERT_LOCALLY', |     stack: 'Error: unable to get local issuer certificate\n' + |       '    at AxiosError.from (/QVS/src/node_modules/axios/dist/node/axios.cjs:837:14)\n' + |       '    at RedirectableRequest.handleRequestError (/QVS/src/node_modules/axios/dist/node/axios.cjs:3087:25)\n' + |       '    at RedirectableRequest.emit (node:events:530:35)\n' + |       '    at eventHandlers.<computed> (/QVS/src/node_modules/follow-redirects/index.js:38:24)\n' + |       '    at ClientRequest.emit (node:events:518:28)\n' + |       '    at TLSSocket.socketErrorListener (node:_http_client:495:9)\n' + |       '    at TLSSocket.emit (node:events:518:28)\n' + |       '    at emitErrorNT (node:internal/streams/destroy:169:8)\n' + |       '    at emitErrorCloseNT (node:internal/streams/destroy:128:3)\n' + |       '    at process.processTicksAndRejections (node:internal/process/task_queues:82:21)\n' + |       '    at Axios.request (/QVS/src/node_modules/axios/dist/node/axios.cjs:3877:41)\n' + |       '    at process.processTicksAndRejections (node:internal/process/task_queues:95:5)\n' + |       '    at async nodeRequest (/QVS/src/common/nodeRequestHandler.js:88:26)\n' + |       '    at async RequestHandler.sendRequest (/QVS/src/common/requestHandler.js:109:25)' |   } | } Request ended with an error. Retrying call host with address: api.trustedservices.intel.com:443 ... Attempt number: 1 out of 2
[2024-02-13T13:53:44.727Z] [INFO] [QuoteVerificationService requestHandler.js:106] [hostname:SGXrinkai pid:1] [reqId=81d78946066945ec8e2f61fb569d8ec5] Sending request to: https://api.trustedservices.intel.com:443/sgx/certification/v4/qe/identity?update=standard
[2024-02-13T13:53:44.744Z] [INFO] [QuoteVerificationService requestHandler.js:106] [hostname:SGXrinkai pid:1] [reqId=81d78946066945ec8e2f61fb569d8ec5] Sending request to: https://api.trustedservices.intel.com:443/sgx/certification/v4/tcb?fmspc=00706A100000&update=standard
[2024-02-13T13:53:44.759Z] [INFO] [QuoteVerificationService requestHandler.js:106] [hostname:SGXrinkai pid:1] [reqId=81d78946066945ec8e2f61fb569d8ec5] Sending request to: https://api.trustedservices.intel.com:443/sgx/certification/v3/pckcrl?ca=processor&encoding=der
[2024-02-13T13:53:45.278Z] [ERROR] [QuoteVerificationService requestHandler.js:136] [hostname:SGXrinkai pid:1] [reqId=81d78946066945ec8e2f61fb569d8ec5] Error while trying to GET https://api.trustedservices.intel.com:443/sgx/certification/v4/qe/identity?update=standard: {"details":{"code":"UNABLE_TO_GET_ISSUER_CERT_LOCALLY","stack":"Error: unable to get local issuer certificate\n    at AxiosError.from (/QVS/src/node_modules/axios/dist/node/axios.cjs:837:14)\n    at RedirectableRequest.handleRequestError (/QVS/src/node_modules/axios/dist/node/axios.cjs:3087:25)\n    at RedirectableRequest.emit (node:events:530:35)\n    at eventHandlers.<computed> (/QVS/src/node_modules/follow-redirects/index.js:38:24)\n    at ClientRequest.emit (node:events:518:28)\n    at TLSSocket.socketErrorListener (node:_http_client:495:9)\n    at TLSSocket.emit (node:events:518:28)\n    at emitErrorNT (node:internal/streams/destroy:169:8)\n    at emitErrorCloseNT (node:internal/streams/destroy:128:3)\n    at process.processTicksAndRejections (node:internal/process/task_queues:82:21)\n    at Axios.request (/QVS/src/node_modules/axios/dist/node/axios.cjs:3877:41)\n    at process.processTicksAndRejections (node:internal/process/task_queues:95:5)\n    at async nodeRequest (/QVS/src/common/nodeRequestHandler.js:88:26)\n    at async RequestHandler.sendRequest (/QVS/src/common/requestHandler.js:109:25)"},"name":"Error","message":"unable to get local issuer certificate","stack":"Error: unable to get local issuer certificate\n    at RequestHandler.sendRequest (/QVS/src/common/requestHandler.js:134:55)\n    at process.processTicksAndRejections (node:internal/process/task_queues:95:5)"}
[2024-02-13T13:53:45.296Z] [ERROR] [QuoteVerificationService requestHandler.js:136] [hostname:SGXrinkai pid:1] [reqId=81d78946066945ec8e2f61fb569d8ec5] Error while trying to GET https://api.trustedservices.intel.com:443/sgx/certification/v4/tcb?fmspc=00706A100000&update=standard: {"details":{"code":"UNABLE_TO_GET_ISSUER_CERT_LOCALLY","stack":"Error: unable to get local issuer certificate\n    at AxiosError.from (/QVS/src/node_modules/axios/dist/node/axios.cjs:837:14)\n    at RedirectableRequest.handleRequestError (/QVS/src/node_modules/axios/dist/node/axios.cjs:3087:25)\n    at RedirectableRequest.emit (node:events:530:35)\n    at eventHandlers.<computed> (/QVS/src/node_modules/follow-redirects/index.js:38:24)\n    at ClientRequest.emit (node:events:518:28)\n    at TLSSocket.socketErrorListener (node:_http_client:495:9)\n    at TLSSocket.emit (node:events:518:28)\n    at emitErrorNT (node:internal/streams/destroy:169:8)\n    at emitErrorCloseNT (node:internal/streams/destroy:128:3)\n    at process.processTicksAndRejections (node:internal/process/task_queues:82:21)\n    at Axios.request (/QVS/src/node_modules/axios/dist/node/axios.cjs:3877:41)\n    at process.processTicksAndRejections (node:internal/process/task_queues:95:5)\n    at async nodeRequest (/QVS/src/common/nodeRequestHandler.js:88:26)\n    at async RequestHandler.sendRequest (/QVS/src/common/requestHandler.js:109:25)"},"name":"Error","message":"unable to get local issuer certificate","stack":"Error: unable to get local issuer certificate\n    at RequestHandler.sendRequest (/QVS/src/common/requestHandler.js:134:55)\n    at process.processTicksAndRejections (node:internal/process/task_queues:95:5)"}
[2024-02-13T13:53:45.307Z] [ERROR] [QuoteVerificationService requestHandler.js:136] [hostname:SGXrinkai pid:1] [reqId=81d78946066945ec8e2f61fb569d8ec5] Error while trying to GET https://api.trustedservices.intel.com:443/sgx/certification/v3/pckcrl?ca=processor&encoding=der: {"details":{"code":"UNABLE_TO_GET_ISSUER_CERT_LOCALLY","stack":"Error: unable to get local issuer certificate\n    at AxiosError.from (/QVS/src/node_modules/axios/dist/node/axios.cjs:837:14)\n    at RedirectableRequest.handleRequestError (/QVS/src/node_modules/axios/dist/node/axios.cjs:3087:25)\n    at RedirectableRequest.emit (node:events:530:35)\n    at eventHandlers.<computed> (/QVS/src/node_modules/follow-redirects/index.js:38:24)\n    at ClientRequest.emit (node:events:518:28)\n    at TLSSocket.socketErrorListener (node:_http_client:495:9)\n    at TLSSocket.emit (node:events:518:28)\n    at emitErrorNT (node:internal/streams/destroy:169:8)\n    at emitErrorCloseNT (node:internal/streams/destroy:128:3)\n    at process.processTicksAndRejections (node:internal/process/task_queues:82:21)\n    at Axios.request (/QVS/src/node_modules/axios/dist/node/axios.cjs:3877:41)\n    at process.processTicksAndRejections (node:internal/process/task_queues:95:5)\n    at async nodeRequest (/QVS/src/common/nodeRequestHandler.js:88:26)\n    at async RequestHandler.sendRequest (/QVS/src/common/requestHandler.js:109:25)"},"name":"Error","message":"unable to get local issuer certificate","stack":"Error: unable to get local issuer certificate\n    at RequestHandler.sendRequest (/QVS/src/common/requestHandler.js:134:55)\n    at process.processTicksAndRejections (node:internal/process/task_queues:95:5)"}
[2024-02-13T13:53:45.307Z] [WARN] [QuoteVerificationService requestHandler.js:134] [hostname:SGXrinkai pid:1] [reqId=81d78946066945ec8e2f61fb569d8ec5] RuntimeError: unable to get local issuer certificate |     at RequestHandler.sendRequest (/QVS/src/common/requestHandler.js:134:55) |     at process.processTicksAndRejections (node:internal/process/task_queues:95:5) { |   details: { |     code: 'UNABLE_TO_GET_ISSUER_CERT_LOCALLY', |     stack: 'Error: unable to get local issuer certificate\n' + |       '    at AxiosError.from (/QVS/src/node_modules/axios/dist/node/axios.cjs:837:14)\n' + |       '    at RedirectableRequest.handleRequestError (/QVS/src/node_modules/axios/dist/node/axios.cjs:3087:25)\n' + |       '    at RedirectableRequest.emit (node:events:530:35)\n' + |       '    at eventHandlers.<computed> (/QVS/src/node_modules/follow-redirects/index.js:38:24)\n' + |       '    at ClientRequest.emit (node:events:518:28)\n' + |       '    at TLSSocket.socketErrorListener (node:_http_client:495:9)\n' + |       '    at TLSSocket.emit (node:events:518:28)\n' + |       '    at emitErrorNT (node:internal/streams/destroy:169:8)\n' + |       '    at emitErrorCloseNT (node:internal/streams/destroy:128:3)\n' + |       '    at process.processTicksAndRejections (node:internal/process/task_queues:82:21)\n' + |       '    at Axios.request (/QVS/src/node_modules/axios/dist/node/axios.cjs:3877:41)\n' + |       '    at process.processTicksAndRejections (node:internal/process/task_queues:95:5)\n' + |       '    at async nodeRequest (/QVS/src/common/nodeRequestHandler.js:88:26)\n' + |       '    at async RequestHandler.sendRequest (/QVS/src/common/requestHandler.js:109:25)' |   } | } Request ended with an error. Retrying call host with address: api.trustedservices.intel.com:443 ... Attempt number: 2 out of 2
[2024-02-13T13:53:45.607Z] [INFO] [QuoteVerificationService requestHandler.js:106] [hostname:SGXrinkai pid:1] [reqId=81d78946066945ec8e2f61fb569d8ec5] Sending request to: https://api.trustedservices.intel.com:443/sgx/certification/v3/pckcrl?ca=processor&encoding=der
[2024-02-13T13:53:46.142Z] [ERROR] [QuoteVerificationService requestHandler.js:136] [hostname:SGXrinkai pid:1] [reqId=81d78946066945ec8e2f61fb569d8ec5] Error while trying to GET https://api.trustedservices.intel.com:443/sgx/certification/v3/pckcrl?ca=processor&encoding=der: {"details":{"code":"UNABLE_TO_GET_ISSUER_CERT_LOCALLY","stack":"Error: unable to get local issuer certificate\n    at AxiosError.from (/QVS/src/node_modules/axios/dist/node/axios.cjs:837:14)\n    at RedirectableRequest.handleRequestError (/QVS/src/node_modules/axios/dist/node/axios.cjs:3087:25)\n    at RedirectableRequest.emit (node:events:530:35)\n    at eventHandlers.<computed> (/QVS/src/node_modules/follow-redirects/index.js:38:24)\n    at ClientRequest.emit (node:events:518:28)\n    at TLSSocket.socketErrorListener (node:_http_client:495:9)\n    at TLSSocket.emit (node:events:518:28)\n    at emitErrorNT (node:internal/streams/destroy:169:8)\n    at emitErrorCloseNT (node:internal/streams/destroy:128:3)\n    at process.processTicksAndRejections (node:internal/process/task_queues:82:21)\n    at Axios.request (/QVS/src/node_modules/axios/dist/node/axios.cjs:3877:41)\n    at process.processTicksAndRejections (node:internal/process/task_queues:95:5)\n    at async nodeRequest (/QVS/src/common/nodeRequestHandler.js:88:26)\n    at async RequestHandler.sendRequest (/QVS/src/common/requestHandler.js:109:25)"},"name":"Error","message":"unable to get local issuer certificate","stack":"Error: unable to get local issuer certificate\n    at RequestHandler.sendRequest (/QVS/src/common/requestHandler.js:134:55)\n    at process.processTicksAndRejections (node:internal/process/task_queues:95:5)"}
[2024-02-13T13:53:46.142Z] [ERROR] [QuoteVerificationService verifyAttestationEvidence.js:490] [hostname:SGXrinkai pid:1] [reqId=81d78946066945ec8e2f61fb569d8ec5] Error: Failed to retrieve required TcbInfo. PCS returned status: undefined |     at readTcbInfoAndIssuerChainFromResponse (/QVS/src/handlers/verifyAttestationEvidence.js:490:19) |     at verifyAttestationEvidence (/QVS/src/handlers/verifyAttestationEvidence.js:154:60) |     at process.processTicksAndRejections (node:internal/process/task_queues:95:5) |     at async bodyParser (/QVS/src/node_modules/koa-bodyparser/index.js:78:5) |     at async /QVS/src/koa/middleware/errorHandler.js:46:13 { |   status: 500 | }
[2024-02-13T13:53:46.144Z] [ERROR] [QuoteVerificationService configureCtxLoggerAndLogResponse.js:59] [hostname:SGXrinkai pid:1] [reqId=81d78946066945ec8e2f61fb569d8ec5]   --> response POST /attestation/sgx/dcap/v1/report 500 took 2195ms [headers={"request-id":"81d78946066945ec8e2f61fb569d8ec5","content-length":"0"} body='']
[2024-02-13T13:54:35.603Z] [INFO] [QuoteVerificationService requestHandler.js:106] [hostname:SGXrinkai pid:1] [reqId=fb4a18bf044346d2838d56f333ce39ef] Sending request to: https://localhost:8797/health
[2024-02-13T13:55:35.633Z] [INFO] [QuoteVerificationService requestHandler.js:106] [hostname:SGXrinkai pid:1] [reqId=1e25acc2449546a9ac401c2a320eceb6] Sending request to: https://localhost:8797/health
[2024-02-13T13:55:36.732Z] [INFO] [QuoteVerificationService requestId.js:75] [hostname:SGXrinkai pid:1] [reqId=287fd5fc76134054a65edeb46f31099c]   <-- request POST /attestation/sgx/dcap/v1/report [headers={"host":"localhost:8799","user-agent":"curl/7.81.0","accept":"*/*","content-type":"application/json","content-length":"6181"}]
[2024-02-13T13:55:36.744Z] [INFO] [QuoteVerificationService requestHandler.js:106] [hostname:SGXrinkai pid:1] [reqId=287fd5fc76134054a65edeb46f31099c] Sending request to: https://api.trustedservices.intel.com:443/sgx/certification/v4/tcb?fmspc=00706A100000&update=standard
[2024-02-13T13:55:36.747Z] [INFO] [QuoteVerificationService requestHandler.js:106] [hostname:SGXrinkai pid:1] [reqId=287fd5fc76134054a65edeb46f31099c] Sending request to: https://api.trustedservices.intel.com:443/sgx/certification/v4/qe/identity?update=standard
[2024-02-13T13:55:36.751Z] [INFO] [QuoteVerificationService requestHandler.js:106] [hostname:SGXrinkai pid:1] [reqId=287fd5fc76134054a65edeb46f31099c] Sending request to: https://api.trustedservices.intel.com:443/sgx/certification/v3/pckcrl?ca=processor&encoding=der
[2024-02-13T13:55:36.755Z] [INFO] [QuoteVerificationService requestHandler.js:106] [hostname:SGXrinkai pid:1] [reqId=287fd5fc76134054a65edeb46f31099c] Sending request to: https://certificates.trustedservices.intel.com:443/IntelSGXRootCA.der
[2024-02-13T13:55:36.964Z] [ERROR] [QuoteVerificationService requestHandler.js:136] [hostname:SGXrinkai pid:1] [reqId=287fd5fc76134054a65edeb46f31099c] Error while trying to GET https://certificates.trustedservices.intel.com:443/IntelSGXRootCA.der: {"details":{"code":"SELF_SIGNED_CERT_IN_CHAIN","stack":"Error: self-signed certificate in certificate chain\n    at AxiosError.from (/QVS/src/node_modules/axios/dist/node/axios.cjs:837:14)\n    at RedirectableRequest.handleRequestError (/QVS/src/node_modules/axios/dist/node/axios.cjs:3087:25)\n    at RedirectableRequest.emit (node:events:530:35)\n    at eventHandlers.<computed> (/QVS/src/node_modules/follow-redirects/index.js:38:24)\n    at ClientRequest.emit (node:events:518:28)\n    at TLSSocket.socketErrorListener (node:_http_client:495:9)\n    at TLSSocket.emit (node:events:518:28)\n    at emitErrorNT (node:internal/streams/destroy:169:8)\n    at emitErrorCloseNT (node:internal/streams/destroy:128:3)\n    at process.processTicksAndRejections (node:internal/process/task_queues:82:21)\n    at Axios.request (/QVS/src/node_modules/axios/dist/node/axios.cjs:3877:41)\n    at process.processTicksAndRejections (node:internal/process/task_queues:95:5)\n    at async nodeRequest (/QVS/src/common/nodeRequestHandler.js:88:26)\n    at async RequestHandler.sendRequest (/QVS/src/common/requestHandler.js:109:25)"},"name":"Error","message":"self-signed certificate in certificate chain","stack":"Error: self-signed certificate in certificate chain\n    at RequestHandler.sendRequest (/QVS/src/common/requestHandler.js:134:55)\n    at process.processTicksAndRejections (node:internal/process/task_queues:95:5)"}
[2024-02-13T13:55:36.965Z] [WARN] [QuoteVerificationService requestHandler.js:134] [hostname:SGXrinkai pid:1] [reqId=287fd5fc76134054a65edeb46f31099c] RuntimeError: self-signed certificate in certificate chain |     at RequestHandler.sendRequest (/QVS/src/common/requestHandler.js:134:55) |     at process.processTicksAndRejections (node:internal/process/task_queues:95:5) { |   details: { |     code: 'SELF_SIGNED_CERT_IN_CHAIN', |     stack: 'Error: self-signed certificate in certificate chain\n' + |       '    at AxiosError.from (/QVS/src/node_modules/axios/dist/node/axios.cjs:837:14)\n' + |       '    at RedirectableRequest.handleRequestError (/QVS/src/node_modules/axios/dist/node/axios.cjs:3087:25)\n' + |       '    at RedirectableRequest.emit (node:events:530:35)\n' + |       '    at eventHandlers.<computed> (/QVS/src/node_modules/follow-redirects/index.js:38:24)\n' + |       '    at ClientRequest.emit (node:events:518:28)\n' + |       '    at TLSSocket.socketErrorListener (node:_http_client:495:9)\n' + |       '    at TLSSocket.emit (node:events:518:28)\n' + |       '    at emitErrorNT (node:internal/streams/destroy:169:8)\n' + |       '    at emitErrorCloseNT (node:internal/streams/destroy:128:3)\n' + |       '    at process.processTicksAndRejections (node:internal/process/task_queues:82:21)\n' + |       '    at Axios.request (/QVS/src/node_modules/axios/dist/node/axios.cjs:3877:41)\n' + |       '    at process.processTicksAndRejections (node:internal/process/task_queues:95:5)\n' + |       '    at async nodeRequest (/QVS/src/common/nodeRequestHandler.js:88:26)\n' + |       '    at async RequestHandler.sendRequest (/QVS/src/common/requestHandler.js:109:25)' |   } | } Request ended with an error. Retrying call host with address: certificates.trustedservices.intel.com:443 ... Attempt number: 1 out of 2
[2024-02-13T13:55:37.065Z] [INFO] [QuoteVerificationService requestHandler.js:106] [hostname:SGXrinkai pid:1] [reqId=287fd5fc76134054a65edeb46f31099c] Sending request to: https://certificates.trustedservices.intel.com:443/IntelSGXRootCA.der
[2024-02-13T13:55:37.111Z] [ERROR] [QuoteVerificationService requestHandler.js:136] [hostname:SGXrinkai pid:1] [reqId=287fd5fc76134054a65edeb46f31099c] Error while trying to GET https://certificates.trustedservices.intel.com:443/IntelSGXRootCA.der: {"details":{"code":"SELF_SIGNED_CERT_IN_CHAIN","stack":"Error: self-signed certificate in certificate chain\n    at AxiosError.from (/QVS/src/node_modules/axios/dist/node/axios.cjs:837:14)\n    at RedirectableRequest.handleRequestError (/QVS/src/node_modules/axios/dist/node/axios.cjs:3087:25)\n    at RedirectableRequest.emit (node:events:530:35)\n    at eventHandlers.<computed> (/QVS/src/node_modules/follow-redirects/index.js:38:24)\n    at ClientRequest.emit (node:events:518:28)\n    at TLSSocket.socketErrorListener (node:_http_client:495:9)\n    at TLSSocket.emit (node:events:518:28)\n    at emitErrorNT (node:internal/streams/destroy:169:8)\n    at emitErrorCloseNT (node:internal/streams/destroy:128:3)\n    at process.processTicksAndRejections (node:internal/process/task_queues:82:21)\n    at Axios.request (/QVS/src/node_modules/axios/dist/node/axios.cjs:3877:41)\n    at process.processTicksAndRejections (node:internal/process/task_queues:95:5)\n    at async nodeRequest (/QVS/src/common/nodeRequestHandler.js:88:26)\n    at async RequestHandler.sendRequest (/QVS/src/common/requestHandler.js:109:25)"},"name":"Error","message":"self-signed certificate in certificate chain","stack":"Error: self-signed certificate in certificate chain\n    at RequestHandler.sendRequest (/QVS/src/common/requestHandler.js:134:55)\n    at process.processTicksAndRejections (node:internal/process/task_queues:95:5)"}
[2024-02-13T13:55:37.111Z] [WARN] [QuoteVerificationService requestHandler.js:134] [hostname:SGXrinkai pid:1] [reqId=287fd5fc76134054a65edeb46f31099c] RuntimeError: self-signed certificate in certificate chain |     at RequestHandler.sendRequest (/QVS/src/common/requestHandler.js:134:55) |     at process.processTicksAndRejections (node:internal/process/task_queues:95:5) { |   details: { |     code: 'SELF_SIGNED_CERT_IN_CHAIN', |     stack: 'Error: self-signed certificate in certificate chain\n' + |       '    at AxiosError.from (/QVS/src/node_modules/axios/dist/node/axios.cjs:837:14)\n' + |       '    at RedirectableRequest.handleRequestError (/QVS/src/node_modules/axios/dist/node/axios.cjs:3087:25)\n' + |       '    at RedirectableRequest.emit (node:events:530:35)\n' + |       '    at eventHandlers.<computed> (/QVS/src/node_modules/follow-redirects/index.js:38:24)\n' + |       '    at ClientRequest.emit (node:events:518:28)\n' + |       '    at TLSSocket.socketErrorListener (node:_http_client:495:9)\n' + |       '    at TLSSocket.emit (node:events:518:28)\n' + |       '    at emitErrorNT (node:internal/streams/destroy:169:8)\n' + |       '    at emitErrorCloseNT (node:internal/streams/destroy:128:3)\n' + |       '    at process.processTicksAndRejections (node:internal/process/task_queues:82:21)\n' + |       '    at Axios.request (/QVS/src/node_modules/axios/dist/node/axios.cjs:3877:41)\n' + |       '    at process.processTicksAndRejections (node:internal/process/task_queues:95:5)\n' + |       '    at async nodeRequest (/QVS/src/common/nodeRequestHandler.js:88:26)\n' + |       '    at async RequestHandler.sendRequest (/QVS/src/common/requestHandler.js:109:25)' |   } | } Request ended with an error. Retrying call host with address: certificates.trustedservices.intel.com:443 ... Attempt number: 2 out of 2
[2024-02-13T13:55:37.412Z] [INFO] [QuoteVerificationService requestHandler.js:106] [hostname:SGXrinkai pid:1] [reqId=287fd5fc76134054a65edeb46f31099c] Sending request to: https://certificates.trustedservices.intel.com:443/IntelSGXRootCA.der
[2024-02-13T13:55:37.428Z] [ERROR] [QuoteVerificationService requestHandler.js:136] [hostname:SGXrinkai pid:1] [reqId=287fd5fc76134054a65edeb46f31099c] Error while trying to GET https://api.trustedservices.intel.com:443/sgx/certification/v4/qe/identity?update=standard: {"details":{"code":"UNABLE_TO_GET_ISSUER_CERT_LOCALLY","stack":"Error: unable to get local issuer certificate\n    at AxiosError.from (/QVS/src/node_modules/axios/dist/node/axios.cjs:837:14)\n    at RedirectableRequest.handleRequestError (/QVS/src/node_modules/axios/dist/node/axios.cjs:3087:25)\n    at RedirectableRequest.emit (node:events:530:35)\n    at eventHandlers.<computed> (/QVS/src/node_modules/follow-redirects/index.js:38:24)\n    at ClientRequest.emit (node:events:518:28)\n    at TLSSocket.socketErrorListener (node:_http_client:495:9)\n    at TLSSocket.emit (node:events:518:28)\n    at emitErrorNT (node:internal/streams/destroy:169:8)\n    at emitErrorCloseNT (node:internal/streams/destroy:128:3)\n    at process.processTicksAndRejections (node:internal/process/task_queues:82:21)\n    at Axios.request (/QVS/src/node_modules/axios/dist/node/axios.cjs:3877:41)\n    at process.processTicksAndRejections (node:internal/process/task_queues:95:5)\n    at async nodeRequest (/QVS/src/common/nodeRequestHandler.js:88:26)\n    at async RequestHandler.sendRequest (/QVS/src/common/requestHandler.js:109:25)"},"name":"Error","message":"unable to get local issuer certificate","stack":"Error: unable to get local issuer certificate\n    at RequestHandler.sendRequest (/QVS/src/common/requestHandler.js:134:55)\n    at process.processTicksAndRejections (node:internal/process/task_queues:95:5)"}
[2024-02-13T13:55:37.428Z] [WARN] [QuoteVerificationService requestHandler.js:134] [hostname:SGXrinkai pid:1] [reqId=287fd5fc76134054a65edeb46f31099c] RuntimeError: unable to get local issuer certificate |     at RequestHandler.sendRequest (/QVS/src/common/requestHandler.js:134:55) |     at process.processTicksAndRejections (node:internal/process/task_queues:95:5) { |   details: { |     code: 'UNABLE_TO_GET_ISSUER_CERT_LOCALLY', |     stack: 'Error: unable to get local issuer certificate\n' + |       '    at AxiosError.from (/QVS/src/node_modules/axios/dist/node/axios.cjs:837:14)\n' + |       '    at RedirectableRequest.handleRequestError (/QVS/src/node_modules/axios/dist/node/axios.cjs:3087:25)\n' + |       '    at RedirectableRequest.emit (node:events:530:35)\n' + |       '    at eventHandlers.<computed> (/QVS/src/node_modules/follow-redirects/index.js:38:24)\n' + |       '    at ClientRequest.emit (node:events:518:28)\n' + |       '    at TLSSocket.socketErrorListener (node:_http_client:495:9)\n' + |       '    at TLSSocket.emit (node:events:518:28)\n' + |       '    at emitErrorNT (node:internal/streams/destroy:169:8)\n' + |       '    at emitErrorCloseNT (node:internal/streams/destroy:128:3)\n' + |       '    at process.processTicksAndRejections (node:internal/process/task_queues:82:21)\n' + |       '    at Axios.request (/QVS/src/node_modules/axios/dist/node/axios.cjs:3877:41)\n' + |       '    at process.processTicksAndRejections (node:internal/process/task_queues:95:5)\n' + |       '    at async nodeRequest (/QVS/src/common/nodeRequestHandler.js:88:26)\n' + |       '    at async RequestHandler.sendRequest (/QVS/src/common/requestHandler.js:109:25)' |   } | } Request ended with an error. Retrying call host with address: api.trustedservices.intel.com:443 ... Attempt number: 1 out of 1
[2024-02-13T13:55:37.454Z] [ERROR] [QuoteVerificationService requestHandler.js:136] [hostname:SGXrinkai pid:1] [reqId=287fd5fc76134054a65edeb46f31099c] Error while trying to GET https://api.trustedservices.intel.com:443/sgx/certification/v4/tcb?fmspc=00706A100000&update=standard: {"details":{"code":"UNABLE_TO_GET_ISSUER_CERT_LOCALLY","stack":"Error: unable to get local issuer certificate\n    at AxiosError.from (/QVS/src/node_modules/axios/dist/node/axios.cjs:837:14)\n    at RedirectableRequest.handleRequestError (/QVS/src/node_modules/axios/dist/node/axios.cjs:3087:25)\n    at RedirectableRequest.emit (node:events:530:35)\n    at eventHandlers.<computed> (/QVS/src/node_modules/follow-redirects/index.js:38:24)\n    at ClientRequest.emit (node:events:518:28)\n    at TLSSocket.socketErrorListener (node:_http_client:495:9)\n    at TLSSocket.emit (node:events:518:28)\n    at emitErrorNT (node:internal/streams/destroy:169:8)\n    at emitErrorCloseNT (node:internal/streams/destroy:128:3)\n    at process.processTicksAndRejections (node:internal/process/task_queues:82:21)\n    at Axios.request (/QVS/src/node_modules/axios/dist/node/axios.cjs:3877:41)\n    at process.processTicksAndRejections (node:internal/process/task_queues:95:5)\n    at async nodeRequest (/QVS/src/common/nodeRequestHandler.js:88:26)\n    at async RequestHandler.sendRequest (/QVS/src/common/requestHandler.js:109:25)"},"name":"Error","message":"unable to get local issuer certificate","stack":"Error: unable to get local issuer certificate\n    at RequestHandler.sendRequest (/QVS/src/common/requestHandler.js:134:55)\n    at process.processTicksAndRejections (node:internal/process/task_queues:95:5)"}
[2024-02-13T13:55:37.455Z] [WARN] [QuoteVerificationService requestHandler.js:134] [hostname:SGXrinkai pid:1] [reqId=287fd5fc76134054a65edeb46f31099c] RuntimeError: unable to get local issuer certificate |     at RequestHandler.sendRequest (/QVS/src/common/requestHandler.js:134:55) |     at process.processTicksAndRejections (node:internal/process/task_queues:95:5) { |   details: { |     code: 'UNABLE_TO_GET_ISSUER_CERT_LOCALLY', |     stack: 'Error: unable to get local issuer certificate\n' + |       '    at AxiosError.from (/QVS/src/node_modules/axios/dist/node/axios.cjs:837:14)\n' + |       '    at RedirectableRequest.handleRequestError (/QVS/src/node_modules/axios/dist/node/axios.cjs:3087:25)\n' + |       '    at RedirectableRequest.emit (node:events:530:35)\n' + |       '    at eventHandlers.<computed> (/QVS/src/node_modules/follow-redirects/index.js:38:24)\n' + |       '    at ClientRequest.emit (node:events:518:28)\n' + |       '    at TLSSocket.socketErrorListener (node:_http_client:495:9)\n' + |       '    at TLSSocket.emit (node:events:518:28)\n' + |       '    at emitErrorNT (node:internal/streams/destroy:169:8)\n' + |       '    at emitErrorCloseNT (node:internal/streams/destroy:128:3)\n' + |       '    at process.processTicksAndRejections (node:internal/process/task_queues:82:21)\n' + |       '    at Axios.request (/QVS/src/node_modules/axios/dist/node/axios.cjs:3877:41)\n' + |       '    at process.processTicksAndRejections (node:internal/process/task_queues:95:5)\n' + |       '    at async nodeRequest (/QVS/src/common/nodeRequestHandler.js:88:26)\n' + |       '    at async RequestHandler.sendRequest (/QVS/src/common/requestHandler.js:109:25)' |   } | } Request ended with an error. Retrying call host with address: api.trustedservices.intel.com:443 ... Attempt number: 1 out of 1
[2024-02-13T13:55:37.459Z] [ERROR] [QuoteVerificationService requestHandler.js:136] [hostname:SGXrinkai pid:1] [reqId=287fd5fc76134054a65edeb46f31099c] Error while trying to GET https://certificates.trustedservices.intel.com:443/IntelSGXRootCA.der: {"details":{"code":"SELF_SIGNED_CERT_IN_CHAIN","stack":"Error: self-signed certificate in certificate chain\n    at AxiosError.from (/QVS/src/node_modules/axios/dist/node/axios.cjs:837:14)\n    at RedirectableRequest.handleRequestError (/QVS/src/node_modules/axios/dist/node/axios.cjs:3087:25)\n    at RedirectableRequest.emit (node:events:530:35)\n    at eventHandlers.<computed> (/QVS/src/node_modules/follow-redirects/index.js:38:24)\n    at ClientRequest.emit (node:events:518:28)\n    at TLSSocket.socketErrorListener (node:_http_client:495:9)\n    at TLSSocket.emit (node:events:518:28)\n    at emitErrorNT (node:internal/streams/destroy:169:8)\n    at emitErrorCloseNT (node:internal/streams/destroy:128:3)\n    at process.processTicksAndRejections (node:internal/process/task_queues:82:21)\n    at Axios.request (/QVS/src/node_modules/axios/dist/node/axios.cjs:3877:41)\n    at process.processTicksAndRejections (node:internal/process/task_queues:95:5)\n    at async nodeRequest (/QVS/src/common/nodeRequestHandler.js:88:26)\n    at async RequestHandler.sendRequest (/QVS/src/common/requestHandler.js:109:25)"},"name":"Error","message":"self-signed certificate in certificate chain","stack":"Error: self-signed certificate in certificate chain\n    at RequestHandler.sendRequest (/QVS/src/common/requestHandler.js:134:55)\n    at process.processTicksAndRejections (node:internal/process/task_queues:95:5)"}
[2024-02-13T13:55:37.482Z] [ERROR] [QuoteVerificationService requestHandler.js:136] [hostname:SGXrinkai pid:1] [reqId=287fd5fc76134054a65edeb46f31099c] Error while trying to GET https://api.trustedservices.intel.com:443/sgx/certification/v3/pckcrl?ca=processor&encoding=der: {"details":{"code":"UNABLE_TO_GET_ISSUER_CERT_LOCALLY","stack":"Error: unable to get local issuer certificate\n    at AxiosError.from (/QVS/src/node_modules/axios/dist/node/axios.cjs:837:14)\n    at RedirectableRequest.handleRequestError (/QVS/src/node_modules/axios/dist/node/axios.cjs:3087:25)\n    at RedirectableRequest.emit (node:events:530:35)\n    at eventHandlers.<computed> (/QVS/src/node_modules/follow-redirects/index.js:38:24)\n    at ClientRequest.emit (node:events:518:28)\n    at TLSSocket.socketErrorListener (node:_http_client:495:9)\n    at TLSSocket.emit (node:events:518:28)\n    at emitErrorNT (node:internal/streams/destroy:169:8)\n    at emitErrorCloseNT (node:internal/streams/destroy:128:3)\n    at process.processTicksAndRejections (node:internal/process/task_queues:82:21)\n    at Axios.request (/QVS/src/node_modules/axios/dist/node/axios.cjs:3877:41)\n    at process.processTicksAndRejections (node:internal/process/task_queues:95:5)\n    at async nodeRequest (/QVS/src/common/nodeRequestHandler.js:88:26)\n    at async RequestHandler.sendRequest (/QVS/src/common/requestHandler.js:109:25)"},"name":"Error","message":"unable to get local issuer certificate","stack":"Error: unable to get local issuer certificate\n    at RequestHandler.sendRequest (/QVS/src/common/requestHandler.js:134:55)\n    at process.processTicksAndRejections (node:internal/process/task_queues:95:5)"}
[2024-02-13T13:55:37.483Z] [WARN] [QuoteVerificationService requestHandler.js:134] [hostname:SGXrinkai pid:1] [reqId=287fd5fc76134054a65edeb46f31099c] RuntimeError: unable to get local issuer certificate |     at RequestHandler.sendRequest (/QVS/src/common/requestHandler.js:134:55) |     at process.processTicksAndRejections (node:internal/process/task_queues:95:5) { |   details: { |     code: 'UNABLE_TO_GET_ISSUER_CERT_LOCALLY', |     stack: 'Error: unable to get local issuer certificate\n' + |       '    at AxiosError.from (/QVS/src/node_modules/axios/dist/node/axios.cjs:837:14)\n' + |       '    at RedirectableRequest.handleRequestError (/QVS/src/node_modules/axios/dist/node/axios.cjs:3087:25)\n' + |       '    at RedirectableRequest.emit (node:events:530:35)\n' + |       '    at eventHandlers.<computed> (/QVS/src/node_modules/follow-redirects/index.js:38:24)\n' + |       '    at ClientRequest.emit (node:events:518:28)\n' + |       '    at TLSSocket.socketErrorListener (node:_http_client:495:9)\n' + |       '    at TLSSocket.emit (node:events:518:28)\n' + |       '    at emitErrorNT (node:internal/streams/destroy:169:8)\n' + |       '    at emitErrorCloseNT (node:internal/streams/destroy:128:3)\n' + |       '    at process.processTicksAndRejections (node:internal/process/task_queues:82:21)\n' + |       '    at Axios.request (/QVS/src/node_modules/axios/dist/node/axios.cjs:3877:41)\n' + |       '    at process.processTicksAndRejections (node:internal/process/task_queues:95:5)\n' + |       '    at async nodeRequest (/QVS/src/common/nodeRequestHandler.js:88:26)\n' + |       '    at async RequestHandler.sendRequest (/QVS/src/common/requestHandler.js:109:25)' |   } | } Request ended with an error. Retrying call host with address: api.trustedservices.intel.com:443 ... Attempt number: 1 out of 2
[2024-02-13T13:55:37.529Z] [INFO] [QuoteVerificationService requestHandler.js:106] [hostname:SGXrinkai pid:1] [reqId=287fd5fc76134054a65edeb46f31099c] Sending request to: https://api.trustedservices.intel.com:443/sgx/certification/v4/qe/identity?update=standard
[2024-02-13T13:55:37.555Z] [INFO] [QuoteVerificationService requestHandler.js:106] [hostname:SGXrinkai pid:1] [reqId=287fd5fc76134054a65edeb46f31099c] Sending request to: https://api.trustedservices.intel.com:443/sgx/certification/v4/tcb?fmspc=00706A100000&update=standard
[2024-02-13T13:55:37.583Z] [INFO] [QuoteVerificationService requestHandler.js:106] [hostname:SGXrinkai pid:1] [reqId=287fd5fc76134054a65edeb46f31099c] Sending request to: https://api.trustedservices.intel.com:443/sgx/certification/v3/pckcrl?ca=processor&encoding=der
[2024-02-13T13:55:38.071Z] [ERROR] [QuoteVerificationService requestHandler.js:136] [hostname:SGXrinkai pid:1] [reqId=287fd5fc76134054a65edeb46f31099c] Error while trying to GET https://api.trustedservices.intel.com:443/sgx/certification/v4/qe/identity?update=standard: {"details":{"code":"UNABLE_TO_GET_ISSUER_CERT_LOCALLY","stack":"Error: unable to get local issuer certificate\n    at AxiosError.from (/QVS/src/node_modules/axios/dist/node/axios.cjs:837:14)\n    at RedirectableRequest.handleRequestError (/QVS/src/node_modules/axios/dist/node/axios.cjs:3087:25)\n    at RedirectableRequest.emit (node:events:530:35)\n    at eventHandlers.<computed> (/QVS/src/node_modules/follow-redirects/index.js:38:24)\n    at ClientRequest.emit (node:events:518:28)\n    at TLSSocket.socketErrorListener (node:_http_client:495:9)\n    at TLSSocket.emit (node:events:518:28)\n    at emitErrorNT (node:internal/streams/destroy:169:8)\n    at emitErrorCloseNT (node:internal/streams/destroy:128:3)\n    at process.processTicksAndRejections (node:internal/process/task_queues:82:21)\n    at Axios.request (/QVS/src/node_modules/axios/dist/node/axios.cjs:3877:41)\n    at process.processTicksAndRejections (node:internal/process/task_queues:95:5)\n    at async nodeRequest (/QVS/src/common/nodeRequestHandler.js:88:26)\n    at async RequestHandler.sendRequest (/QVS/src/common/requestHandler.js:109:25)"},"name":"Error","message":"unable to get local issuer certificate","stack":"Error: unable to get local issuer certificate\n    at RequestHandler.sendRequest (/QVS/src/common/requestHandler.js:134:55)\n    at process.processTicksAndRejections (node:internal/process/task_queues:95:5)"}
[2024-02-13T13:55:38.093Z] [ERROR] [QuoteVerificationService requestHandler.js:136] [hostname:SGXrinkai pid:1] [reqId=287fd5fc76134054a65edeb46f31099c] Error while trying to GET https://api.trustedservices.intel.com:443/sgx/certification/v4/tcb?fmspc=00706A100000&update=standard: {"details":{"code":"UNABLE_TO_GET_ISSUER_CERT_LOCALLY","stack":"Error: unable to get local issuer certificate\n    at AxiosError.from (/QVS/src/node_modules/axios/dist/node/axios.cjs:837:14)\n    at RedirectableRequest.handleRequestError (/QVS/src/node_modules/axios/dist/node/axios.cjs:3087:25)\n    at RedirectableRequest.emit (node:events:530:35)\n    at eventHandlers.<computed> (/QVS/src/node_modules/follow-redirects/index.js:38:24)\n    at ClientRequest.emit (node:events:518:28)\n    at TLSSocket.socketErrorListener (node:_http_client:495:9)\n    at TLSSocket.emit (node:events:518:28)\n    at emitErrorNT (node:internal/streams/destroy:169:8)\n    at emitErrorCloseNT (node:internal/streams/destroy:128:3)\n    at process.processTicksAndRejections (node:internal/process/task_queues:82:21)\n    at Axios.request (/QVS/src/node_modules/axios/dist/node/axios.cjs:3877:41)\n    at process.processTicksAndRejections (node:internal/process/task_queues:95:5)\n    at async nodeRequest (/QVS/src/common/nodeRequestHandler.js:88:26)\n    at async RequestHandler.sendRequest (/QVS/src/common/requestHandler.js:109:25)"},"name":"Error","message":"unable to get local issuer certificate","stack":"Error: unable to get local issuer certificate\n    at RequestHandler.sendRequest (/QVS/src/common/requestHandler.js:134:55)\n    at process.processTicksAndRejections (node:internal/process/task_queues:95:5)"}
[2024-02-13T13:55:38.106Z] [ERROR] [QuoteVerificationService requestHandler.js:136] [hostname:SGXrinkai pid:1] [reqId=287fd5fc76134054a65edeb46f31099c] Error while trying to GET https://api.trustedservices.intel.com:443/sgx/certification/v3/pckcrl?ca=processor&encoding=der: {"details":{"code":"UNABLE_TO_GET_ISSUER_CERT_LOCALLY","stack":"Error: unable to get local issuer certificate\n    at AxiosError.from (/QVS/src/node_modules/axios/dist/node/axios.cjs:837:14)\n    at RedirectableRequest.handleRequestError (/QVS/src/node_modules/axios/dist/node/axios.cjs:3087:25)\n    at RedirectableRequest.emit (node:events:530:35)\n    at eventHandlers.<computed> (/QVS/src/node_modules/follow-redirects/index.js:38:24)\n    at ClientRequest.emit (node:events:518:28)\n    at TLSSocket.socketErrorListener (node:_http_client:495:9)\n    at TLSSocket.emit (node:events:518:28)\n    at emitErrorNT (node:internal/streams/destroy:169:8)\n    at emitErrorCloseNT (node:internal/streams/destroy:128:3)\n    at process.processTicksAndRejections (node:internal/process/task_queues:82:21)\n    at Axios.request (/QVS/src/node_modules/axios/dist/node/axios.cjs:3877:41)\n    at process.processTicksAndRejections (node:internal/process/task_queues:95:5)\n    at async nodeRequest (/QVS/src/common/nodeRequestHandler.js:88:26)\n    at async RequestHandler.sendRequest (/QVS/src/common/requestHandler.js:109:25)"},"name":"Error","message":"unable to get local issuer certificate","stack":"Error: unable to get local issuer certificate\n    at RequestHandler.sendRequest (/QVS/src/common/requestHandler.js:134:55)\n    at process.processTicksAndRejections (node:internal/process/task_queues:95:5)"}
[2024-02-13T13:55:38.107Z] [WARN] [QuoteVerificationService requestHandler.js:134] [hostname:SGXrinkai pid:1] [reqId=287fd5fc76134054a65edeb46f31099c] RuntimeError: unable to get local issuer certificate |     at RequestHandler.sendRequest (/QVS/src/common/requestHandler.js:134:55) |     at process.processTicksAndRejections (node:internal/process/task_queues:95:5) { |   details: { |     code: 'UNABLE_TO_GET_ISSUER_CERT_LOCALLY', |     stack: 'Error: unable to get local issuer certificate\n' + |       '    at AxiosError.from (/QVS/src/node_modules/axios/dist/node/axios.cjs:837:14)\n' + |       '    at RedirectableRequest.handleRequestError (/QVS/src/node_modules/axios/dist/node/axios.cjs:3087:25)\n' + |       '    at RedirectableRequest.emit (node:events:530:35)\n' + |       '    at eventHandlers.<computed> (/QVS/src/node_modules/follow-redirects/index.js:38:24)\n' + |       '    at ClientRequest.emit (node:events:518:28)\n' + |       '    at TLSSocket.socketErrorListener (node:_http_client:495:9)\n' + |       '    at TLSSocket.emit (node:events:518:28)\n' + |       '    at emitErrorNT (node:internal/streams/destroy:169:8)\n' + |       '    at emitErrorCloseNT (node:internal/streams/destroy:128:3)\n' + |       '    at process.processTicksAndRejections (node:internal/process/task_queues:82:21)\n' + |       '    at Axios.request (/QVS/src/node_modules/axios/dist/node/axios.cjs:3877:41)\n' + |       '    at process.processTicksAndRejections (node:internal/process/task_queues:95:5)\n' + |       '    at async nodeRequest (/QVS/src/common/nodeRequestHandler.js:88:26)\n' + |       '    at async RequestHandler.sendRequest (/QVS/src/common/requestHandler.js:109:25)' |   } | } Request ended with an error. Retrying call host with address: api.trustedservices.intel.com:443 ... Attempt number: 2 out of 2
[2024-02-13T13:55:38.407Z] [INFO] [QuoteVerificationService requestHandler.js:106] [hostname:SGXrinkai pid:1] [reqId=287fd5fc76134054a65edeb46f31099c] Sending request to: https://api.trustedservices.intel.com:443/sgx/certification/v3/pckcrl?ca=processor&encoding=der
[2024-02-13T13:55:38.941Z] [ERROR] [QuoteVerificationService requestHandler.js:136] [hostname:SGXrinkai pid:1] [reqId=287fd5fc76134054a65edeb46f31099c] Error while trying to GET https://api.trustedservices.intel.com:443/sgx/certification/v3/pckcrl?ca=processor&encoding=der: {"details":{"code":"UNABLE_TO_GET_ISSUER_CERT_LOCALLY","stack":"Error: unable to get local issuer certificate\n    at AxiosError.from (/QVS/src/node_modules/axios/dist/node/axios.cjs:837:14)\n    at RedirectableRequest.handleRequestError (/QVS/src/node_modules/axios/dist/node/axios.cjs:3087:25)\n    at RedirectableRequest.emit (node:events:530:35)\n    at eventHandlers.<computed> (/QVS/src/node_modules/follow-redirects/index.js:38:24)\n    at ClientRequest.emit (node:events:518:28)\n    at TLSSocket.socketErrorListener (node:_http_client:495:9)\n    at TLSSocket.emit (node:events:518:28)\n    at emitErrorNT (node:internal/streams/destroy:169:8)\n    at emitErrorCloseNT (node:internal/streams/destroy:128:3)\n    at process.processTicksAndRejections (node:internal/process/task_queues:82:21)\n    at Axios.request (/QVS/src/node_modules/axios/dist/node/axios.cjs:3877:41)\n    at process.processTicksAndRejections (node:internal/process/task_queues:95:5)\n    at async nodeRequest (/QVS/src/common/nodeRequestHandler.js:88:26)\n    at async RequestHandler.sendRequest (/QVS/src/common/requestHandler.js:109:25)"},"name":"Error","message":"unable to get local issuer certificate","stack":"Error: unable to get local issuer certificate\n    at RequestHandler.sendRequest (/QVS/src/common/requestHandler.js:134:55)\n    at process.processTicksAndRejections (node:internal/process/task_queues:95:5)"}
[2024-02-13T13:55:38.941Z] [ERROR] [QuoteVerificationService verifyAttestationEvidence.js:490] [hostname:SGXrinkai pid:1] [reqId=287fd5fc76134054a65edeb46f31099c] Error: Failed to retrieve required TcbInfo. PCS returned status: undefined |     at readTcbInfoAndIssuerChainFromResponse (/QVS/src/handlers/verifyAttestationEvidence.js:490:19) |     at verifyAttestationEvidence (/QVS/src/handlers/verifyAttestationEvidence.js:154:60) |     at process.processTicksAndRejections (node:internal/process/task_queues:95:5) |     at async bodyParser (/QVS/src/node_modules/koa-bodyparser/index.js:78:5) |     at async /QVS/src/koa/middleware/errorHandler.js:46:13 { |   status: 500 | }
[2024-02-13T13:55:38.943Z] [ERROR] [QuoteVerificationService configureCtxLoggerAndLogResponse.js:59] [hostname:SGXrinkai pid:1] [reqId=287fd5fc76134054a65edeb46f31099c]   --> response POST /attestation/sgx/dcap/v1/report 500 took 2211ms [headers={"request-id":"287fd5fc76134054a65edeb46f31099c","content-length":"0"} body='']
